{"name": "testCreateRecipe", "status": "broken", "statusDetails": {"message": "django.db.utils.OperationalError: no such table: VEG_REC_recipe", "trace": "self = <django.db.backends.utils.CursorDebugWrapper object at 0x00000175607848D0>, sql = 'DELETE FROM \"VEG_REC_recipe\"', params = ()\nignored_wrapper_args = (False, {'connection': <DatabaseWrapper vendor='sqlite' alias='default'>, 'cursor': <django.db.backends.utils.CursorDebugWrapper object at 0x00000175607848D0>})\n\n    def _execute(self, sql, params, *ignored_wrapper_args):\n        # Raise a warning during app initialization (stored_app_configs is only\n        # ever set during testing).\n        if not apps.ready and not apps.stored_app_configs:\n            warnings.warn(self.APPS_NOT_READY_WARNING_MSG, category=RuntimeWarning)\n        self.db.validate_no_broken_transaction()\n        with self.db.wrap_database_errors:\n            if params is None:\n                # params default might be backend specific.\n                return self.cursor.execute(sql)\n            else:\n>               return self.cursor.execute(sql, params)\n\n..\\venv\\Lib\\site-packages\\django\\db\\backends\\utils.py:105: \n_ _ _ _ _ _ _ _ _ _ _ _ _ _ _ _ _ _ _ _ _ _ _ _ _ _ _ _ _ _ _ _ _ _ _ _ _ _ _ _ _ _ _ _ _ _ _ _ _ _ _ _ _ _ _ _ _ _ _ _ _ _ _ _ _ _ _ _ _ _ _ _ _ _ _ _ _ _ _ _ _ _ _ _ _ _ _ _ _ _ _ _ _ _ _ _ _ _ _ _ _ _ _ _ _ _ _ _ _ _ _ _ _ \n\nself = <django.db.backends.sqlite3.base.SQLiteCursorWrapper object at 0x000001756033BEC0>, query = 'DELETE FROM \"VEG_REC_recipe\"', params = ()\n\n    def execute(self, query, params=None):\n        if params is None:\n            return super().execute(query)\n        # Extract names if params is a mapping, i.e. \"pyformat\" style is used.\n        param_names = list(params) if isinstance(params, Mapping) else None\n        query = self.convert_query(query, param_names=param_names)\n>       return super().execute(query, params)\nE       sqlite3.OperationalError: no such table: VEG_REC_recipe\n\n..\\venv\\Lib\\site-packages\\django\\db\\backends\\sqlite3\\base.py:328: OperationalError\n\nThe above exception was the direct cause of the following exception:\n\nself = <VEG_REC.tests.testRecipe testMethod=testCreateRecipe>\n\n    def tearDown(self):\n        # Delete the created Recipe objects\n>       Recipe.objects.all().delete()\n\ntests.py:78: \n_ _ _ _ _ _ _ _ _ _ _ _ _ _ _ _ _ _ _ _ _ _ _ _ _ _ _ _ _ _ _ _ _ _ _ _ _ _ _ _ _ _ _ _ _ _ _ _ _ _ _ _ _ _ _ _ _ _ _ _ _ _ _ _ _ _ _ _ _ _ _ _ _ _ _ _ _ _ _ _ _ _ _ _ _ _ _ _ _ _ _ _ _ _ _ _ _ _ _ _ _ _ _ _ _ _ _ _ _ _ _ _ _ \n..\\venv\\Lib\\site-packages\\django\\db\\models\\query.py:1186: in delete\n    deleted, _rows_count = collector.delete()\n..\\venv\\Lib\\site-packages\\django\\db\\models\\deletion.py:472: in delete\n    count = qs._raw_delete(using=self.using)\n..\\venv\\Lib\\site-packages\\django\\db\\models\\query.py:1208: in _raw_delete\n    cursor = query.get_compiler(using).execute_sql(CURSOR)\n..\\venv\\Lib\\site-packages\\django\\db\\models\\sql\\compiler.py:1562: in execute_sql\n    cursor.execute(sql, params)\n..\\venv\\Lib\\site-packages\\django\\db\\backends\\utils.py:122: in execute\n    return super().execute(sql, params)\n..\\venv\\Lib\\site-packages\\django\\db\\backends\\utils.py:79: in execute\n    return self._execute_with_wrappers(\n..\\venv\\Lib\\site-packages\\django\\db\\backends\\utils.py:92: in _execute_with_wrappers\n    return executor(sql, params, many, context)\n..\\venv\\Lib\\site-packages\\django\\db\\backends\\utils.py:100: in _execute\n    with self.db.wrap_database_errors:\n..\\venv\\Lib\\site-packages\\django\\db\\utils.py:91: in __exit__\n    raise dj_exc_value.with_traceback(traceback) from exc_value\n..\\venv\\Lib\\site-packages\\django\\db\\backends\\utils.py:105: in _execute\n    return self.cursor.execute(sql, params)\n_ _ _ _ _ _ _ _ _ _ _ _ _ _ _ _ _ _ _ _ _ _ _ _ _ _ _ _ _ _ _ _ _ _ _ _ _ _ _ _ _ _ _ _ _ _ _ _ _ _ _ _ _ _ _ _ _ _ _ _ _ _ _ _ _ _ _ _ _ _ _ _ _ _ _ _ _ _ _ _ _ _ _ _ _ _ _ _ _ _ _ _ _ _ _ _ _ _ _ _ _ _ _ _ _ _ _ _ _ _ _ _ _ \n\nself = <django.db.backends.sqlite3.base.SQLiteCursorWrapper object at 0x000001756033BEC0>, query = 'DELETE FROM \"VEG_REC_recipe\"', params = ()\n\n    def execute(self, query, params=None):\n        if params is None:\n            return super().execute(query)\n        # Extract names if params is a mapping, i.e. \"pyformat\" style is used.\n        param_names = list(params) if isinstance(params, Mapping) else None\n        query = self.convert_query(query, param_names=param_names)\n>       return super().execute(query, params)\nE       django.db.utils.OperationalError: no such table: VEG_REC_recipe\n\n..\\venv\\Lib\\site-packages\\django\\db\\backends\\sqlite3\\base.py:328: OperationalError"}, "start": 1706382412323, "stop": 1706382428559, "uuid": "99ac84f1-5b82-431c-a348-c3da13e03bff", "historyId": "9703b05535b94063e97762b158772403", "testCaseId": "9703b05535b94063e97762b158772403", "fullName": "tests.testRecipe#testCreateRecipe", "labels": [{"name": "suite", "value": "tests"}, {"name": "subSuite", "value": "testRecipe"}, {"name": "host", "value": "LAPTOP-85C54M6J"}, {"name": "thread", "value": "19756-MainThread"}, {"name": "framework", "value": "pytest"}, {"name": "language", "value": "cpython3"}, {"name": "package", "value": "tests"}]}